<mujoco>
    <asset>
		<mesh file="STL_files/p_leg.STL"/>
		<mesh file="STL_files/p_leg_frame-1.STL"/>
		<mesh file="STL_files/p_leg_frame_segment_extension-1.STL"/>
		<mesh file="STL_files/p_leg_frame_segment_extension-2.STL"/>
		<mesh file="STL_files/p_leg_frame_support-1.STL"/>
		<mesh file="STL_files/p_leg_l_u1-1.STL"/>
		<mesh file="STL_files/p_leg_l_u2-2.STL"/>
		<mesh file="STL_files/p_leg_l_u3-2.STL"/>
		<mesh file="STL_files/p_leg_l_u4-1.STL"/>
		<mesh file="STL_files/p_leg_l_u5-1.STL"/>
		<mesh file="STL_files/p_leg_l_us1-1.STL"/>
		<mesh file="STL_files/p_leg_l_us2-1.STL"/>
		<mesh file="STL_files/p_leg_l_us3-1.STL"/>
		<mesh file="STL_files/p_leg_l_us3-2.STL"/>
		<mesh file="STL_files/p_leg_s_u1-1.STL"/>
		<mesh file="STL_files/p_leg_s_u2-1.STL"/>
		<mesh file="STL_files/p_leg_s_u3-1.STL"/>
		<mesh file="STL_files/p_leg_s_u4-1.STL"/>
		<mesh file="STL_files/p_leg_s_u5-1.STL"/>
		<mesh file="STL_files/p_leg_s_u6-1.STL"/>
		<mesh file="STL_files/p_leg_s_u7-1.STL"/>
		<mesh file="STL_files/p_leg_s_us1-1.STL"/>
		<mesh file="STL_files/p_leg_s_us2-1.STL"/>
		<mesh file="STL_files/p_pcb-1.STL"/>
		<mesh file="STL_files/p_pzt_1_1.STL"/>
		<mesh file="STL_files/p_pzt_1_2.STL"/>
		<mesh file="STL_files/p_pzt_2_1.STL"/>
		<mesh file="STL_files/p_pzt_2_2.STL"/>
	</asset>

    <default>
		<geom density="0.002"/>
	</default>

	<option gravity="0 0 -9.810"/>

	<worldbody>
        <light diffuse="1 1 1" pos="0 0 1000" dir="0 0 -1"/>
		<geom type="plane" size="1000 1000 0.1" rgba=".9 0 0 1"/>
		<camera name="closeup" pos="55.989 33.954 23.285" xyaxes="-0.462 0.887 -0.000 -0.252 -0.131 0.959"/>

        <body pos="-6.985 0.254 0" euler ="90 0 0" name="p_pcb-1_1" >

			<geom type="mesh" mesh="p_pcb-1" rgba="0.9 0.9 0.9 1"/>
			<joint type="free"/>

			<body pos="0 0 0" name="p_pzt_1_1_1">
				<geom type="mesh" mesh="p_pzt_1_1" rgba="0.9 .9 0.9 1" mass="1"/>
				<body pos="0 0 0" name="p_pzt_1_2_1">
					<geom type="mesh" mesh="p_pzt_1_2" rgba="0.9 .9 0.9 1" mass="1"/>
					<joint name="p_pzt_1_1" type="hinge" axis="1 0 0" pos="3.984 14.141 5.13" range="-2.73 2.73"/>
					<site name="p_pzt_1_1_1_1" pos="6.973 6.019 5.156"/>
					<site name="p_pzt_1_1_1_2" pos="7.473 5.919 5.156"/>
					<site name="p_pzt_1_1_1_3" pos="6.473 5.919 5.156"/>
				</body>
			</body>

			<body pos="0 0 0" name="p_pzt_2_1_1">
				<geom type="mesh" mesh="p_pzt_2_1" rgba="0.9 .9 0.9 1" mass="1"/>
				<body pos="0 0 0" name="p_pzt_2_2_1">
					<geom type="mesh" mesh="p_pzt_2_2" rgba="0.9 .9 0.9 1" mass="1"/>
					<joint name="p_pzt_2_1" type="hinge" axis="1 0 0" pos="3.984 15.641 6.05" range="-2.73 2.73"/>
				</body>
			</body>

			<body pos="0 0 0" name="p_leg_frame-1_1">
				<geom type="mesh" mesh="p_leg_frame-1" rgba="0.9 .9 0.9 1"/>

                <!-- extensions for the multi-legged simulation-->
				<body pos="0 0 0" name="p_leg_frame_segment_extension-1_1">
					<geom type="mesh" mesh="p_leg_frame_segment_extension-1" rgba="0.9 .9 0.9 1"/>
				</body>
				<body pos="0 0 0" name="p_leg_frame_segment_extension-2_1">
					<geom type="mesh" mesh="p_leg_frame_segment_extension-2" rgba="0.9 .9 0.9 1"/>
				</body>

                <!-- lift section -->

				<body pos="0 0 0" name="p_leg_l_u1-1_1">
					<geom type="mesh" mesh="p_leg_l_u1-1" rgba="0.9 .9 0.9 1"/>
					<joint type="hinge" limited="true" range="-28.0 28.0" stiffness="20480" springref="0.0" damping="1024" axis="1 0 0" pos="7.885 6.419 9.106"/>
					<body pos="0 0 0">
						<geom type="mesh" mesh="p_leg_l_u2-2" rgba="0.9 .9 0.9 1"/>
					</body>

                    <!-- lift actuator -->

					<body pos="0 0 0" name="p_leg_l_u3-2_1">
						<geom type="mesh" mesh="p_leg_l_u3-2" rgba="0.9 .9 0.9 1"/>
						<body pos="0 0 0" euler ="0 0 0">
							<geom type="mesh" mesh="p_leg_l_u4-1" rgba="0.9 0.9 0.9 1"/>
                            <joint type="hinge" limited="true" range="-28.0 28.0" stiffness="10240" springref="0.0" damping="512" axis="1 0 0" pos="7.986 5.919 9.056"  />
                            <body pos="0 0 0" name="p_leg_l_u5-1_1">
                                <geom type="mesh" mesh="p_leg_l_u5-1" rgba="0.9 .9 0.9 1"/>
                                <joint type="hinge" limited="true" range="-28.0 28.0" stiffness="17067" springref="0.0" damping="853" axis="1 0 0" pos="6.973 5.919 5.556" />
								<site name="p_pzt_1_1_2_1" pos="6.973 6.019 5.156"/>
								<site name="p_pzt_1_1_2_2" pos="7.473 5.919 5.156"/>
								<site name="p_pzt_1_1_2_3" pos="6.473 5.919 5.156"/>
                            </body>
						</body>
					</body>

                    <!-- lift end-effector -->
					<body pos="0 0 0" >
						<geom type="mesh" mesh="p_leg_l_us1-1" rgba="0.9 .9 0.9 1"/>
						<joint type="hinge" limited="true" range="-28.0 28.0" stiffness="20480" springref="0.0" damping="1024" axis="0 1 0" pos="6.985 5.419 9.106"/>
						<body pos="0 0 0">
							<geom type="mesh" mesh="p_leg_l_us3-2" rgba="0.9 .9 0.9 1"/>
							<body pos="0 0 0" name="p_leg_l_us2-1_1">
								<geom type="mesh" mesh="p_leg_l_us2-1" rgba="0.9 .9 0.9 1"/>
							</body>
						</body>
						<body pos="0 0 0" >
							<geom type="mesh" mesh="p_leg" rgba="0.9 .9 0.9 1"/>
						</body>
					</body>

				</body>

                <!-- swing section -->

				<body pos="0 0 0" name="p_leg_s_u1-1_1">

					<geom type="mesh" mesh="p_leg_s_u1-1" rgba="0.9 .9 0.9 1"/>
					<joint type="hinge" limited="true" range="-28.0 28.0" stiffness="20480" springref="0.0" damping="1024" axis="0 1 0" pos="6.985 7.319 9.106"/>
					<body pos="0 0 0">
						<geom type="mesh" mesh="p_leg_s_u2-1" rgba="0.9 .9 0.9 1"/>
					</body>

                    <!-- swing actuator -->

                    <body pos="0 0 0" name="p_leg_s_u3-1_1">
                        <geom type="mesh" mesh="p_leg_s_u3-1" rgba="0.9 .9 0.9 1"/>
                        <body pos="0 0 0" >
                            <geom type="mesh" mesh="p_leg_s_u4-1" rgba="0.9 .9 0.9 1"/>
                            <joint type="hinge" limited="true" range="-28.0 28.0" stiffness="10240" springref="0.0" damping="512" axis="0 1 0" pos="6.535 7.407 9.056"/>
                            <body pos="0 0 0">
                                <geom type="mesh" mesh="p_leg_s_u5-1" rgba="0.9 .9 0.9 1"/>
                                <body pos="0 0 0">
                                    <geom type="mesh" mesh="p_leg_s_u6-1" rgba="0.9 .9 0.9 1"/>	
                                    <body pos="0 0 0" name="p_leg_s_u7-1_1">
                                        <geom type="mesh" mesh="p_leg_s_u7-1" rgba="0.9 .9 0.9 1"/>
                                        <joint type="hinge" limited="true" range="-28.0 28.0" stiffness="17067" springref="0.0" damping="853" axis="1 0 0" pos="7.16 7.407 6.479"/>
                                    </body>
                                </body>
                            </body>
                        </body>
                    </body>

                    <!-- swing end-effector -->

                    <body pos="0 0 0" name="p_leg_s_us1-1_1">
						<geom type="mesh" mesh="p_leg_s_us1-1" rgba="0.9 .9 0.9 1"/>
						<joint type="hinge" limited="true" range="-28.0 28.0" stiffness="17067" springref="0.0" damping="853" axis="1 0 0" pos="5.884 6.419 9.106"/>
						<body pos="0 0 0" name = "p_leg_l_us3-1_1">
							<geom type="mesh" mesh="p_leg_l_us3-1" rgba="0.9 .9 0.9 1"/>
						</body>
						<body pos="0 0 0" name = "p_leg_s_us2-1_1">
							<geom type="mesh" mesh="p_leg_s_us2-1" rgba="0.9 .9 0.9 1"/>
						</body>
					</body>
				</body>
			</body>

		</body>

        <body pos="-0.254 -6.985 0" euler ="90 90 0" name="p_pcb-1_2" >

			<geom type="mesh" mesh="p_pcb-1" rgba="0.9 0.9 0.9 1"/>
			<joint type="free"/>

			<body pos="0 0 0" name="p_pzt_1_1_2">
				<geom type="mesh" mesh="p_pzt_1_1" rgba="0.9 .9 0.9 1" mass="1"/>
				<body pos="0 0 0" name="p_pzt_1_2_2">
					<geom type="mesh" mesh="p_pzt_1_2" rgba="0.9 .9 0.9 1" mass="1"/>
					<joint name="p_pzt_1_2" type="hinge" axis="1 0 0" pos="3.984 14.141 5.13" range="-2.73 2.73"/>
				</body>
			</body>

			<body pos="0 0 0" name="p_pzt_2_1_2">
				<geom type="mesh" mesh="p_pzt_2_1" rgba="0.9 .9 0.9 1" mass="1"/>
				<body pos="0 0 0" name="p_pzt_2_2_2">
					<geom type="mesh" mesh="p_pzt_2_2" rgba="0.9 .9 0.9 1" mass="1"/>
					<joint name="p_pzt_2_2" type="hinge" axis="1 0 0" pos="3.984 15.641 6.05" range="-2.73 2.73"/>
				</body>
			</body>
			
			<body pos="0 0 0" name="p_leg_frame-1_2">
				<geom type="mesh" mesh="p_leg_frame-1" rgba="0.9 .9 0.9 1"/>

                <!-- extensions for the multi-legged simulation-->
				<body pos="0 0 0" name="p_leg_frame_segment_extension-1_2">
					<geom type="mesh" mesh="p_leg_frame_segment_extension-1" rgba="0.9 .9 0.9 1"/>
				</body>
				<body pos="0 0 0" name="p_leg_frame_segment_extension-2_2">
					<geom type="mesh" mesh="p_leg_frame_segment_extension-2" rgba="0.9 .9 0.9 1"/>
				</body>

                <!-- lift section -->

				<body pos="0 0 0" name="p_leg_l_u1-1_2">
					<geom type="mesh" mesh="p_leg_l_u1-1" rgba="0.9 .9 0.9 1"/>
					<joint type="hinge" limited="true" range="-28.0 28.0" stiffness="20480" springref="0.0" damping="1024" axis="1 0 0" pos="7.885 6.419 9.106"/>
					<body pos="0 0 0">
						<geom type="mesh" mesh="p_leg_l_u2-2" rgba="0.9 .9 0.9 1"/>
					</body>

                    <!-- lift actuator -->

					<body pos="0 0 0" name="p_leg_l_u3-2_2">
						<geom type="mesh" mesh="p_leg_l_u3-2" rgba="0.9 .9 0.9 1"/>
						<body pos="0 0 0" euler ="0 0 0">
							<geom type="mesh" mesh="p_leg_l_u4-1" rgba="0.9 0.9 0.9 1"/>
                            <joint type="hinge" limited="true" range="-28.0 28.0" stiffness="10240" springref="0.0" damping="512" axis="1 0 0" pos="7.986 5.919 9.056"  />
                            <body pos="0 0 0" name="p_leg_l_u5-1_2">
                                <geom type="mesh" mesh="p_leg_l_u5-1" rgba="0.9 .9 0.9 1"/>
                                <joint type="hinge" limited="true" range="-28.0 28.0" stiffness="17067" springref="0.0" damping="853" axis="1 0 0" pos="6.973 5.919 5.556" />
                            </body>
						</body>
					</body>

                    <!-- lift end-effector -->
					<body pos="0 0 0" >
						<geom type="mesh" mesh="p_leg_l_us1-1" rgba="0.9 .9 0.9 1"/>
						<joint type="hinge" limited="true" range="-28.0 28.0" stiffness="20480" springref="0.0" damping="1024" axis="0 1 0" pos="6.985 5.419 9.106"/>
						<body pos="0 0 0">
							<geom type="mesh" mesh="p_leg_l_us3-2" rgba="0.9 .9 0.9 1"/>
							<body pos="0 0 0" name="p_leg_l_us2-1_2">
								<geom type="mesh" mesh="p_leg_l_us2-1" rgba="0.9 .9 0.9 1"/>
							</body>
						</body>
						<body pos="0 0 0" >
							<geom type="mesh" mesh="p_leg" rgba="0.9 .9 0.9 1"/>
						</body>
					</body>

				</body>

                <!-- swing section -->

				<body pos="0 0 0" name="p_leg_s_u1-1_2">

					<geom type="mesh" mesh="p_leg_s_u1-1" rgba="0.9 .9 0.9 1"/>
					<joint type="hinge" limited="true" range="-28.0 28.0" stiffness="20480" springref="0.0" damping="1024" axis="0 1 0" pos="6.985 7.319 9.106"/>
					<body pos="0 0 0">
						<geom type="mesh" mesh="p_leg_s_u2-1" rgba="0.9 .9 0.9 1"/>
					</body>

                    <!-- swing actuator -->

                    <body pos="0 0 0" name="p_leg_s_u3-1_2">
                        <geom type="mesh" mesh="p_leg_s_u3-1" rgba="0.9 .9 0.9 1"/>
                        <body pos="0 0 0" >
                            <geom type="mesh" mesh="p_leg_s_u4-1" rgba="0.9 .9 0.9 1"/>
                            <joint type="hinge" limited="true" range="-28.0 28.0" stiffness="10240" springref="0.0" damping="512" axis="0 1 0" pos="6.535 7.407 9.056"/>
                            <body pos="0 0 0">
                                <geom type="mesh" mesh="p_leg_s_u5-1" rgba="0.9 .9 0.9 1"/>
                                <body pos="0 0 0">
                                    <geom type="mesh" mesh="p_leg_s_u6-1" rgba="0.9 .9 0.9 1"/>	
                                    <body pos="0 0 0" name="p_leg_s_u7-1_2">
                                        <geom type="mesh" mesh="p_leg_s_u7-1" rgba="0.9 .9 0.9 1"/>
                                        <joint type="hinge" limited="true" range="-28.0 28.0" stiffness="17067" springref="0.0" damping="853" axis="1 0 0" pos="7.16 7.407 6.479"/>
                                    </body>
                                </body>
                            </body>
                        </body>
                    </body>

                    <!-- swing end-effector -->

                    <body pos="0 0 0" name="p_leg_s_us1-1_2">
						<geom type="mesh" mesh="p_leg_s_us1-1" rgba="0.9 .9 0.9 1"/>
						<joint type="hinge" limited="true" range="-28.0 28.0" stiffness="17067" springref="0.0" damping="853" axis="1 0 0" pos="5.884 6.419 9.106"/>
						<body pos="0 0 0" name = "p_leg_l_us3-1_2">
							<geom type="mesh" mesh="p_leg_l_us3-1" rgba="0.9 .9 0.9 1"/>
						</body>
						<body pos="0 0 0" name = "p_leg_s_us2-1_2">
							<geom type="mesh" mesh="p_leg_s_us2-1" rgba="0.9 .9 0.9 1"/>
						</body>
					</body>
				</body>
			</body>

		</body>

        <body pos="6.985 -0.254 0" euler ="90 180 0" name="p_pcb-1_3" >

			<geom type="mesh" mesh="p_pcb-1" rgba="0.9 0.9 0.9 1"/>
			<joint type="free"/>

			<body pos="0 0 0" name="p_pzt_1_1_3">
				<geom type="mesh" mesh="p_pzt_1_1" rgba="0.9 .9 0.9 1" mass="1"/>
				<body pos="0 0 0" name="p_pzt_1_2_3">
					<geom type="mesh" mesh="p_pzt_1_2" rgba="0.9 .9 0.9 1" mass="1"/>
					<joint name="p_pzt_1_3" type="hinge" axis="1 0 0" pos="3.984 14.141 5.13" range="-2.73 2.73"/>
				</body>
			</body>

			<body pos="0 0 0" name="p_pzt_2_1_3">
				<geom type="mesh" mesh="p_pzt_2_1" rgba="0.9 .9 0.9 1" mass="1"/>
				<body pos="0 0 0" name="p_pzt_2_2_3">
					<geom type="mesh" mesh="p_pzt_2_2" rgba="0.9 .9 0.9 1" mass="1"/>
					<joint name="p_pzt_2_3" type="hinge" axis="1 0 0" pos="3.984 15.641 6.05" range="-2.73 2.73"/>
				</body>
			</body>

			<body pos="0 0 0" name="p_leg_frame-1_3">
				<geom type="mesh" mesh="p_leg_frame-1" rgba="0.9 .9 0.9 1"/>

                <!-- extensions for the multi-legged simulation-->
				<body pos="0 0 0" name="p_leg_frame_segment_extension-1_3">
					<geom type="mesh" mesh="p_leg_frame_segment_extension-1" rgba="0.9 .9 0.9 1"/>
				</body>
				<body pos="0 0 0" name="p_leg_frame_segment_extension-2_3">
					<geom type="mesh" mesh="p_leg_frame_segment_extension-2" rgba="0.9 .9 0.9 1"/>
				</body>

                <!-- lift section -->

				<body pos="0 0 0" name="p_leg_l_u1-1_3">
					<geom type="mesh" mesh="p_leg_l_u1-1" rgba="0.9 .9 0.9 1"/>
					<joint type="hinge" limited="true" range="-28.0 28.0" stiffness="20480" springref="0.0" damping="1024" axis="1 0 0" pos="7.885 6.419 9.106"/>
					<body pos="0 0 0">
						<geom type="mesh" mesh="p_leg_l_u2-2" rgba="0.9 .9 0.9 1"/>
					</body>

                    <!-- lift actuator -->

					<body pos="0 0 0" name="p_leg_l_u3-2_3">
						<geom type="mesh" mesh="p_leg_l_u3-2" rgba="0.9 .9 0.9 1"/>
						<body pos="0 0 0" euler ="0 0 0">
							<geom type="mesh" mesh="p_leg_l_u4-1" rgba="0.9 0.9 0.9 1"/>
                            <joint type="hinge" limited="true" range="-28.0 28.0" stiffness="10240" springref="0.0" damping="512" axis="1 0 0" pos="7.986 5.919 9.056"  />
                            <body pos="0 0 0" name="p_leg_l_u5-1_3">
                                <geom type="mesh" mesh="p_leg_l_u5-1" rgba="0.9 .9 0.9 1"/>
                                <joint type="hinge" limited="true" range="-28.0 28.0" stiffness="17067" springref="0.0" damping="853" axis="1 0 0" pos="6.973 5.919 5.556" />
                            </body>
						</body>
					</body>

                    <!-- lift end-effector -->
					<body pos="0 0 0" >
						<geom type="mesh" mesh="p_leg_l_us1-1" rgba="0.9 .9 0.9 1"/>
						<joint type="hinge" limited="true" range="-28.0 28.0" stiffness="20480" springref="0.0" damping="1024" axis="0 1 0" pos="6.985 5.419 9.106"/>
						<body pos="0 0 0">
							<geom type="mesh" mesh="p_leg_l_us3-2" rgba="0.9 .9 0.9 1"/>
							<body pos="0 0 0" name="p_leg_l_us2-1_3">
								<geom type="mesh" mesh="p_leg_l_us2-1" rgba="0.9 .9 0.9 1"/>
							</body>
						</body>
						<body pos="0 0 0" >
							<geom type="mesh" mesh="p_leg" rgba="0.9 .9 0.9 1"/>
						</body>
					</body>

				</body>

                <!-- swing section -->

				<body pos="0 0 0" name="p_leg_s_u1-1_3">

					<geom type="mesh" mesh="p_leg_s_u1-1" rgba="0.9 .9 0.9 1"/>
					<joint type="hinge" limited="true" range="-28.0 28.0" stiffness="20480" springref="0.0" damping="1024" axis="0 1 0" pos="6.985 7.319 9.106"/>
					<body pos="0 0 0">
						<geom type="mesh" mesh="p_leg_s_u2-1" rgba="0.9 .9 0.9 1"/>
					</body>

                    <!-- swing actuator -->

                    <body pos="0 0 0" name="p_leg_s_u3-1_3">
                        <geom type="mesh" mesh="p_leg_s_u3-1" rgba="0.9 .9 0.9 1"/>
                        <body pos="0 0 0" >
                            <geom type="mesh" mesh="p_leg_s_u4-1" rgba="0.9 .9 0.9 1"/>
                            <joint type="hinge" limited="true" range="-28.0 28.0" stiffness="10240" springref="0.0" damping="512" axis="0 1 0" pos="6.535 7.407 9.056"/>
                            <body pos="0 0 0">
                                <geom type="mesh" mesh="p_leg_s_u5-1" rgba="0.9 .9 0.9 1"/>
                                <body pos="0 0 0">
                                    <geom type="mesh" mesh="p_leg_s_u6-1" rgba="0.9 .9 0.9 1"/>	
                                    <body pos="0 0 0" name="p_leg_s_u7-1_3">
                                        <geom type="mesh" mesh="p_leg_s_u7-1" rgba="0.9 .9 0.9 1"/>
                                        <joint type="hinge" limited="true" range="-28.0 28.0" stiffness="17067" springref="0.0" damping="853" axis="1 0 0" pos="7.16 7.407 6.479"/>
                                    </body>
                                </body>
                            </body>
                        </body>
                    </body>

                    <!-- swing end-effector -->

                    <body pos="0 0 0" name="p_leg_s_us1-1_3">
						<geom type="mesh" mesh="p_leg_s_us1-1" rgba="0.9 .9 0.9 1"/>
						<joint type="hinge" limited="true" range="-28.0 28.0" stiffness="17067" springref="0.0" damping="853" axis="1 0 0" pos="5.884 6.419 9.106"/>
						<body pos="0 0 0" name = "p_leg_l_us3-1_3">
							<geom type="mesh" mesh="p_leg_l_us3-1" rgba="0.9 .9 0.9 1"/>
						</body>
						<body pos="0 0 0" name = "p_leg_s_us2-1_3">
							<geom type="mesh" mesh="p_leg_s_us2-1" rgba="0.9 .9 0.9 1"/>
						</body>
					</body>
				</body>
			</body>

		</body>

        <body pos="0.254 6.985 0" euler ="90 270 0" name="p_pcb-1_4" >

			<geom type="mesh" mesh="p_pcb-1" rgba="0.9 .9 0.9 1"/>
			<joint type="free"/>

			<body pos="0 0 0" name="p_pzt_1_1_4">
				<geom type="mesh" mesh="p_pzt_1_1" rgba="0.9 .9 0.9 1" mass="1"/>
				<body pos="0 0 0" name="p_pzt_1_2_4">
					<geom type="mesh" mesh="p_pzt_1_2" rgba="0.9 .9 0.9 1" mass="1"/>
					<joint name="p_pzt_1_4" type="hinge" axis="1 0 0" pos="3.984 14.141 5.13" range="-2.73 2.73"/>
				</body>
			</body>

			<body pos="0 0 0" name="p_pzt_2_1_4">
				<geom type="mesh" mesh="p_pzt_2_1" rgba="0.9 .9 0.9 1" mass="1"/>
				<body pos="0 0 0" name="p_pzt_2_2_4">
					<geom type="mesh" mesh="p_pzt_2_2" rgba="0.9 .9 0.9 1" mass="1"/>
					<joint name="p_pzt_2_4" type="hinge" axis="1 0 0" pos="3.984 15.641 6.05" range="-2.73 2.73"/>
				</body>
			</body>

			<body pos="0 0 0" name="p_leg_frame-1_4">
				<geom type="mesh" mesh="p_leg_frame-1" rgba="0.9 .9 0.9 1"/>

                <!-- extensions for the multi-legged simulation-->
				<body pos="0 0 0" name="p_leg_frame_segment_extension-1_4">
					<geom type="mesh" mesh="p_leg_frame_segment_extension-1" rgba="0.9 .9 0.9 1"/>
				</body>
				<body pos="0 0 0" name="p_leg_frame_segment_extension-2_4">
					<geom type="mesh" mesh="p_leg_frame_segment_extension-2" rgba="0.9 .9 0.9 1"/>
				</body>

                <!-- lift section -->

				<body pos="0 0 0" name="p_leg_l_u1-1_4">
					<geom type="mesh" mesh="p_leg_l_u1-1" rgba="0.9 .9 0.9 1"/>
					<joint type="hinge" limited="true" range="-28.0 28.0" stiffness="20480" springref="0.0" damping="1024" axis="1 0 0" pos="7.885 6.419 9.106"/>
					<body pos="0 0 0">
						<geom type="mesh" mesh="p_leg_l_u2-2" rgba="0.9 .9 0.9 1"/>
					</body>

                    <!-- lift actuator -->

					<body pos="0 0 0" name="p_leg_l_u3-2_4">
						<geom type="mesh" mesh="p_leg_l_u3-2" rgba="0.9 .9 0.9 1"/>
						<body pos="0 0 0" euler ="0 0 0">
							<geom type="mesh" mesh="p_leg_l_u4-1" rgba="0.9 0.9 0.9 1"/>
                            <joint type="hinge" limited="true" range="-28.0 28.0" stiffness="10240" springref="0.0" damping="512" axis="1 0 0" pos="7.986 5.919 9.056"  />
                            <body pos="0 0 0" name="p_leg_l_u5-1_4">
                                <geom type="mesh" mesh="p_leg_l_u5-1" rgba="0.9 .9 0.9 1"/>
                                <joint type="hinge" limited="true" range="-28.0 28.0" stiffness="17067" springref="0.0" damping="853" axis="1 0 0" pos="6.973 5.919 5.556" />
                            </body>
						</body>
					</body>

                    <!-- lift end-effector -->
					<body pos="0 0 0" >
						<geom type="mesh" mesh="p_leg_l_us1-1" rgba="0.9 .9 0.9 1"/>
						<joint type="hinge" limited="true" range="-28.0 28.0" stiffness="20480" springref="0.0" damping="1024" axis="0 1 0" pos="6.985 5.419 9.106"/>
						<body pos="0 0 0">
							<geom type="mesh" mesh="p_leg_l_us3-2" rgba="0.9 .9 0.9 1"/>
							<body pos="0 0 0" name="p_leg_l_us2-1_4">
								<geom type="mesh" mesh="p_leg_l_us2-1" rgba="0.9 .9 0.9 1"/>
							</body>
						</body>
						<body pos="0 0 0" >
							<geom type="mesh" mesh="p_leg" rgba="0.9 .9 0.9 1"/>
						</body>
					</body>

				</body>

                <!-- swing section -->

				<body pos="0 0 0" name="p_leg_s_u1-1_4">

					<geom type="mesh" mesh="p_leg_s_u1-1" rgba="0.9 .9 0.9 1"/>
					<joint type="hinge" limited="true" range="-28.0 28.0" stiffness="20480" springref="0.0" damping="1024" axis="0 1 0" pos="6.985 7.319 9.106"/>
					<body pos="0 0 0">
						<geom type="mesh" mesh="p_leg_s_u2-1" rgba="0.9 .9 0.9 1"/>
					</body>

                    <!-- swing actuator -->

                    <body pos="0 0 0" name="p_leg_s_u3-1_4">
                        <geom type="mesh" mesh="p_leg_s_u3-1" rgba="0.9 .9 0.9 1"/>
                        <body pos="0 0 0" >
                            <geom type="mesh" mesh="p_leg_s_u4-1" rgba="0.9 .9 0.9 1"/>
                            <joint type="hinge" limited="true" range="-28.0 28.0" stiffness="10240" springref="0.0" damping="512" axis="0 1 0" pos="6.535 7.407 9.056"/>
                            <body pos="0 0 0">
                                <geom type="mesh" mesh="p_leg_s_u5-1" rgba="0.9 .9 0.9 1"/>
                                <body pos="0 0 0">
                                    <geom type="mesh" mesh="p_leg_s_u6-1" rgba="0.9 .9 0.9 1"/>	
                                    <body pos="0 0 0" name="p_leg_s_u7-1_4">
                                        <geom type="mesh" mesh="p_leg_s_u7-1" rgba="0.9 .9 0.9 1"/>
                                        <joint type="hinge" limited="true" range="-28.0 28.0" stiffness="17067" springref="0.0" damping="853" axis="1 0 0" pos="7.16 7.407 6.479"/>
                                    </body>
                                </body>
                            </body>
                        </body>
                    </body>

                    <!-- swing end-effector -->

                    <body pos="0 0 0" name="p_leg_s_us1-1_4">
						<geom type="mesh" mesh="p_leg_s_us1-1" rgba="0.9 .9 0.9 1"/>
						<joint type="hinge" limited="true" range="-28.0 28.0" stiffness="17067" springref="0.0" damping="853" axis="1 0 0" pos="5.884 6.419 9.106"/>
						<body pos="0 0 0" name = "p_leg_l_us3-1_4">
							<geom type="mesh" mesh="p_leg_l_us3-1" rgba="0.9 .9 0.9 1"/>
						</body>
						<body pos="0 0 0" name = "p_leg_s_us2-1_4">
							<geom type="mesh" mesh="p_leg_s_us2-1" rgba="0.9 .9 0.9 1"/>
						</body>
					</body>
				</body>
			</body>

		</body>


	</worldbody>

    <!-- equalities-->

	
    <equality> 
		<!-- leg1-->
		<connect name="link_bar_1" body1="p_leg_l_us2-1_1" body2="p_leg_s_us2-1_1" anchor=" 6.9855 6.4195 12.256 "/>
		<connect name="pzt_1_1_1" body1="p_pzt_1_2_1" body2="p_leg_l_u5-1_1" anchor="6.973 6.019 5.156"/>
		<connect name="pzt_1_1_2" body1="p_pzt_1_2_1" body2="p_leg_l_u5-1_1" anchor="7.473 5.919 5.156"/>
		<connect name="pzt_1_1_3" body1="p_pzt_1_2_1" body2="p_leg_l_u5-1_1" anchor="6.473 5.919 5.156"/>
		<connect name="pzt_2_1_1" body1="p_pzt_2_2_1" body2="p_leg_s_u7-1_1" anchor="7.16 7.507 5.979" />
		<connect name="pzt_2_1_2" body1="p_pzt_2_2_1" body2="p_leg_s_u7-1_1" anchor="7.66 7.407 5.979" />
		<connect name="pzt_2_1_3" body1="p_pzt_2_2_1" body2="p_leg_s_u7-1_1" anchor="6.66 7.407 5.979" />
		<!--weld name="pcb_1_1" body1="p_pcb-1_1" body2="p_leg_s_us1-1_1" /-->
		<!-- leg2-->
		<connect name="link_bar_2" body1="p_leg_l_us2-1_2" body2="p_leg_s_us2-1_2" anchor=" 6.9855 6.4195 12.256 "/>
		<connect name="pzt_1_2_1" body1="p_pzt_1_2_2" body2="p_leg_l_u5-1_2" anchor="6.973 6.019 5.156"/>
		<connect name="pzt_1_2_2" body1="p_pzt_1_2_2" body2="p_leg_l_u5-1_2" anchor="7.473 5.919 5.156"/>
		<connect name="pzt_1_2_3" body1="p_pzt_1_2_2" body2="p_leg_l_u5-1_2" anchor="6.473 5.919 5.156"/>
		<connect name="pzt_2_2_1" body1="p_pzt_2_2_2" body2="p_leg_s_u7-1_2" anchor="7.16 7.507 5.979" />
		<connect name="pzt_2_2_2" body1="p_pzt_2_2_2" body2="p_leg_s_u7-1_2" anchor="7.66 7.407 5.979" />
		<connect name="pzt_2_2_3" body1="p_pzt_2_2_2" body2="p_leg_s_u7-1_2" anchor="6.66 7.407 5.979" />
		<!--weld name="pcb_2" body1="p_pcb-1_2" body2="p_leg_s_us1-1_2" /-->
		<!-- leg3-->
		<connect name="link_bar_3" body1="p_leg_l_us2-1_3" body2="p_leg_s_us2-1_3" anchor=" 6.9855 6.4195 12.256 "/>
		<connect name="pzt_1_3_1" body1="p_pzt_1_2_3" body2="p_leg_l_u5-1_3" anchor="6.973 6.019 5.156"/>
		<connect name="pzt_1_3_2" body1="p_pzt_1_2_3" body2="p_leg_l_u5-1_3" anchor="7.473 5.919 5.156"/>
		<connect name="pzt_1_3_3" body1="p_pzt_1_2_3" body2="p_leg_l_u5-1_3" anchor="6.473 5.919 5.156"/>
		<connect name="pzt_2_3_1" body1="p_pzt_2_2_3" body2="p_leg_s_u7-1_3" anchor="7.16 7.507 5.979" />
		<connect name="pzt_2_3_2" body1="p_pzt_2_2_3" body2="p_leg_s_u7-1_3" anchor="7.66 7.407 5.979" />
		<connect name="pzt_2_3_3" body1="p_pzt_2_2_3" body2="p_leg_s_u7-1_3" anchor="6.66 7.407 5.979" />
		<!--weld name="pcb_3" body1="p_pcb-1_3" body2="p_leg_s_us1-1_3" /-->
		<!-- leg4-->
		<connect name="link_bar_4" body1="p_leg_l_us2-1_4" body2="p_leg_s_us2-1_4" anchor=" 6.9855 6.4195 12.256 "/>
		<connect name="pzt_1_4_1" body1="p_pzt_1_2_4" body2="p_leg_l_u5-1_4" anchor="6.973 6.019 5.156"/>
		<connect name="pzt_1_4_2" body1="p_pzt_1_2_4" body2="p_leg_l_u5-1_4" anchor="7.473 5.919 5.156"/>
		<connect name="pzt_1_4_3" body1="p_pzt_1_2_4" body2="p_leg_l_u5-1_4" anchor="6.473 5.919 5.156"/>
		<connect name="pzt_2_4_1" body1="p_pzt_2_2_4" body2="p_leg_s_u7-1_4" anchor="7.16 7.507 5.979" />
		<connect name="pzt_2_4_2" body1="p_pzt_2_2_4" body2="p_leg_s_u7-1_4" anchor="7.66 7.407 5.979" />
		<connect name="pzt_2_4_3" body1="p_pzt_2_2_4" body2="p_leg_s_u7-1_4" anchor="6.66 7.407 5.979" />
		<!--weld name="pcb_4" body1="p_pcb-1_4" body2="p_leg_s_us1-1_4" /-->
		<!-- interleg-->
		<connect name="joint_1_1" body1="p_leg_frame_segment_extension-1_1" body2="p_leg_frame_segment_extension-2_4" anchor=" 0.184 16.021 7.05 "/>
		<connect name="joint_1_2" body1="p_leg_frame_segment_extension-1_1" body2="p_leg_frame_segment_extension-2_4" anchor=" 0.184 11.021 7.05 "/>
		<connect name="joint_2_1" body1="p_leg_frame_segment_extension-1_4" body2="p_leg_frame_segment_extension-2_3" anchor=" 0.184 16.021 7.05 "/>
		<connect name="joint_2_2" body1="p_leg_frame_segment_extension-1_4" body2="p_leg_frame_segment_extension-2_3" anchor=" 0.184 11.021 7.05 "/>
		<connect name="joint_3_1" body1="p_leg_frame_segment_extension-1_3" body2="p_leg_frame_segment_extension-2_2" anchor=" 0.184 16.021 7.05 "/>
		<connect name="joint_3_2" body1="p_leg_frame_segment_extension-1_3" body2="p_leg_frame_segment_extension-2_2" anchor=" 0.184 11.021 7.05 "/>
		<connect name="joint_4_1" body1="p_leg_frame_segment_extension-1_2" body2="p_leg_frame_segment_extension-2_1" anchor=" 0.184 16.021 7.05 "/>
		<connect name="joint_4_2" body1="p_leg_frame_segment_extension-1_2" body2="p_leg_frame_segment_extension-2_1" anchor=" 0.184 11.021 7.05 "/>
	</equality>


	<!-- actuators -->

	<actuator>
		<motor name="a_pzt_1_1" joint="p_pzt_1_1" gear="500" />
		<motor name="a_pzt_2_1" joint="p_pzt_2_1" gear="500" />
		<motor name="a_pzt_1_2" joint="p_pzt_1_2" gear="500" />
		<motor name="a_pzt_2_2" joint="p_pzt_2_2" gear="500" />
		<motor name="a_pzt_3_1" joint="p_pzt_1_3" gear="500" />
		<motor name="a_pzt_3_2" joint="p_pzt_2_3" gear="500" />
		<motor name="a_pzt_4_1" joint="p_pzt_1_4" gear="500" />
		<motor name="a_pzt_4_2" joint="p_pzt_2_4" gear="500" />
	</actuator>
	
</mujoco>